cloudinary.exceptions.Error: File size too large. Got 13212753. Maximum is 10485760.

settings.py / DEBUG=FALSE